Workbook

Sheet Setup
A1: KPI Tracker — Setup
A3: Reporting Window
A4: Start date | B4: 46023
A5: End date | B5: 46041
A7: Weighting
A8: Skills weight (0–1) | B8: 0.4
A9: Performance weight (0–1) | B9: 0.6
A10: Weights check | B10: =IF(ABS(SUM(B8:B9)-1)<0.0001,"OK","Fix weights (must sum to 1)")
A12: Conversions metric name (optional) | B12: Leads / Purchases
A14: How this workbook is meant to work
A15: 1) Maintain Staff roster and Skills list. 2) Record skill assessments over time (Skill_Assessments). 3) Sync/paste ad performance data into Ads_Raw (daily granularity recommended). 4) Maintain Ads_Mapping so each campaign maps to a Staff_ID (owner). 5) Add Staff-Client targets (Staff_Client_Targets). Dashboards update automatically for the selected reporting window.

Sheet Staff
A1: Staff_ID | B1: Name | C1: Role | D1: Team/Pod | E1: Manager | F1: Start_Date | G1: Active (Y/N) | H1: Notes
A2: S001 | B2: Alex Chen | C2: Media Buyer | D2: Pod A | E2: Biswajit | F2: 45839 | G2: Y
A3: S002 | B3: Priya Nair | C3: Creative Strategist | D3: Pod A | E3: Biswajit | F3: 45915 | G3: Y

Sheet Skills_List
A1: Skill_ID | B1: Skill | C1: Category | D1: Weight | E1: Default_Target_Level (1–5) | F1: Definition / Evidence
A2: SK01 | B2: Account structure & naming | C2: Media Buying | D2: 0.12 | E2: 4 | F2: Consistent naming, clean hierarchy, easy reporting.
A3: SK02 | B3: Creative testing plan | C3: Strategy | D3: 0.12 | E3: 4 | F3: Hypothesis-driven tests; clear variables and success criteria.
A4: SK03 | B4: Pixel/CAPI troubleshooting | C4: Technical | D4: 0.1 | E4: 3 | F4: Diagnose tracking gaps; coordinate fixes; validate events.
A5: SK04 | B5: Budget & bid management | C5: Media Buying | D5: 0.14 | E5: 4 | F5: Controls pacing; avoids learning resets; balances volume/efficiency.
A6: SK05 | B6: Reporting & insights | C6: Analytics | D6: 0.16 | E6: 4 | F6: Explains results, identifies drivers, proposes next actions.
A7: SK06 | B7: Client communication | C7: Client | D7: 0.12 | E7: 4 | F7: Clear updates, expectation setting, handles objections.
A8: SK07 | B8: Creative feedback quality | C8: Creative | D8: 0.12 | E8: 4 | F8: Actionable feedback tied to data and objectives.
A9: SK08 | B9: Process & documentation | C9: Ops | D9: 0.12 | E9: 3 | F9: Maintains SOPs, checklists, handoffs; reduces errors.

Sheet Skill_Assessments
A1: Date | B1: Staff_ID | C1: Skill_ID | D1: Score (1–5) | E1: Assessed_By | F1: Evidence / Notes
A2: 46027 | B2: S001 | C2: SK04 | D2: 3 | E2: Manager | F2: Pacing improved; still volatile week to week.
A3: 46031 | B3: S002 | C3: SK02 | D3: 4 | E3: Manager | F3: Solid plan; next add better segment hypotheses.
A4: 46034 | B4: S001 | C4: SK05 | D4: 3 | E4: Manager | F4: Insights ok; needs clearer next-actions.

Sheet Ads_Mapping
A1: Client | B1: Ad_Account | C1: Campaign | D1: Campaign_ID (optional) | E1: Owner_Staff_ID | F1: Notes | H1: Key (auto) | I1: Owner (auto)
A2: Acme Fitness | B2: Acme_US | C2: Prospecting - Broad | E2: S001 | H2: =IF(A2<>"",A2&"|"&B2&"|"&C2,"") | I2: =E2
A3: Acme Fitness | B3: Acme_US | C3: Retargeting - 30d | E3: S001 | H3: =IF(A3<>"",A3&"|"&B3&"|"&C3,"") | I3: =E3
H4: =IF(A4<>"",A4&"|"&B4&"|"&C4,"") | I4: =E4
H5: =IF(A5<>"",A5&"|"&B5&"|"&C5,"") | I5: =E5
H6: =IF(A6<>"",A6&"|"&B6&"|"&C6,"") | I6: =E6
H7: =IF(A7<>"",A7&"|"&B7&"|"&C7,"") | I7: =E7
H8: =IF(A8<>"",A8&"|"&B8&"|"&C8,"") | I8: =E8
H9: =IF(A9<>"",A9&"|"&B9&"|"&C9,"") | I9: =E9
H10: =IF(A10<>"",A10&"|"&B10&"|"&C10,"") | I10: =E10
H11: =IF(A11<>"",A11&"|"&B11&"|"&C11,"") | I11: =E11
H12: =IF(A12<>"",A12&"|"&B12&"|"&C12,"") | I12: =E12
H13: =IF(A13<>"",A13&"|"&B13&"|"&C13,"") | I13: =E13
H14: =IF(A14<>"",A14&"|"&B14&"|"&C14,"") | I14: =E14
H15: =IF(A15<>"",A15&"|"&B15&"|"&C15,"") | I15: =E15
... H499: =IF(A499<>"",A499&"|"&B499&"|"&C499,"") | I499: =E499

Sheet Ads_Raw
A1: Date | B1: Client | C1: Ad_Account | D1: Campaign | E1: Ad_Set | F1: Ad | G1: Spend | H1: Impressions | I1: Clicks | J1: Conversions | K1: Revenue | L1: Owner_Staff_ID (auto) | M1: Key (auto) | N1: CTR (auto) | O1: CPC (auto) | P1: CPM (auto) | Q1: CPA (auto) | R1: ROAS (auto)
A2: 46040 | B2: Acme Fitness | C2: Acme_US | D2: Prospecting - Broad | E2: AS1 | F2: Ad 1 | G2: 120.5 | H2: 45000 | I2: 620 | J2: 18 | K2: 720 | L2: =IFERROR(VLOOKUP(M2,Ads_Mapping!$H$2:$I$499,2,FALSE),"Unmapped") | M2: =IF(B2<>"",B2&"|"&C2&"|"&D2,"") | N2: =IFERROR(I2/H2,"") | O2: =IFERROR(G2/I2,"") | P2: =IFERROR(G2/H2*1000,"") | Q2: =IFERROR(G2/J2,"") | R2: =IFERROR(K2/G2,"")
A3: 46040 | B3: Acme Fitness | C3: Acme_US | D3: Retargeting - 30d | E3: AS2 | F3: Ad 2 | G3: 80 | H3: 18000 | I3: 260 | J3: 20 | K3: 900 | L3: =IFERROR(VLOOKUP(M3,Ads_Mapping!$H$2:$I$499,2,FALSE),"Unmapped") | M3: =IF(B3<>"",B3&"|"&C3&"|"&D3,"") | N3: =IFERROR(I3/H3,"") | O3: =IFERROR(G3/I3,"") | P3: =IFERROR(G3/H3*1000,"") | Q3: =IFERROR(G3/J3,"") | R3: =IFERROR(K3/G3,"")
L4: =IFERROR(VLOOKUP(M4,Ads_Mapping!$H$2:$I$499,2,FALSE),"Unmapped") | M4: =IF(B4<>"",B4&"|"&C4&"|"&D4,"") | N4: =IFERROR(I4/H4,"") | O4: =IFERROR(G4/I4,"") | P4: =IFERROR(G4/H4*1000,"") | Q4: =IFERROR(G4/J4,"") | R4: =IFERROR(K4/G4,"")
L5: =IFERROR(VLOOKUP(M5,Ads_Mapping!$H$2:$I$499,2,FALSE),"Unmapped") | M5: =IF(B5<>"",B5&"|"&C5&"|"&D5,"") | N5: =IFERROR(I5/H5,"") | O5: =IFERROR(G5/I5,"") | P5: =IFERROR(G5/H5*1000,"") | Q5: =IFERROR(G5/J5,"") | R5: =IFERROR(K5/G5,"")
L6: =IFERROR(VLOOKUP(M6,Ads_Mapping!$H$2:$I$499,2,FALSE),"Unmapped") | M6: =IF(B6<>"",B6&"|"&C6&"|"&D6,"") | N6: =IFERROR(I6/H6,"") | O6: =IFERROR(G6/I6,"") | P6: =IFERROR(G6/H6*1000,"") | Q6: =IFERROR(G6/J6,"") | R6: =IFERROR(K6/G6,"")
L7: =IFERROR(VLOOKUP(M7,Ads_Mapping!$H$2:$I$499,2,FALSE),"Unmapped") | M7: =IF(B7<>"",B7&"|"&C7&"|"&D7,"") | N7: =IFERROR(I7/H7,"") | O7: =IFERROR(G7/I7,"") | P7: =IFERROR(G7/H7*1000,"") | Q7: =IFERROR(G7/J7,"") | R7: =IFERROR(K7/G7,"")
L8: =IFERROR(VLOOKUP(M8,Ads_Mapping!$H$2:$I$499,2,FALSE),"Unmapped") | M8: =IF(B8<>"",B8&"|"&C8&"|"&D8,"") | N8: =IFERROR(I8/H8,"") | O8: =IFERROR(G8/I8,"") | P8: =IFERROR(G8/H8*1000,"") | Q8: =IFERROR(G8/J8,"") | R8: =IFERROR(K8/G8,"")
L9: =IFERROR(VLOOKUP(M9,Ads_Mapping!$H$2:$I$499,2,FALSE),"Unmapped") | M9: =IF(B9<>"",B9&"|"&C9&"|"&D9,"") | N9: =IFERROR(I9/H9,"") | O9: =IFERROR(G9/I9,"") | P9: =IFERROR(G9/H9*1000,"") | Q9: =IFERROR(G9/J9,"") | R9: =IFERROR(K9/G9,"")
L10: =IFERROR(VLOOKUP(M10,Ads_Mapping!$H$2:$I$499,2,FALSE),"Unmapped") | M10: =IF(B10<>"",B10&"|"&C10&"|"&D10,"") | N10: =IFERROR(I10/H10,"") | O10: =IFERROR(G10/I10,"") | P10: =IFERROR(G10/H10*1000,"") | Q10: =IFERROR(G10/J10,"") | R10: =IFERROR(K10/G10,"")
L11: =IFERROR(VLOOKUP(M11,Ads_Mapping!$H$2:$I$499,2,FALSE),"Unmapped") | M11: =IF(B11<>"",B11&"|"&C11&"|"&D11,"") | N11: =IFERROR(I11/H11,"") | O11: =IFERROR(G11/I11,"") | P11: =IFERROR(G11/H11*1000,"") | Q11: =IFERROR(G11/J11,"") | R11: =IFERROR(K11/G11,"")
L12: =IFERROR(VLOOKUP(M12,Ads_Mapping!$H$2:$I$499,2,FALSE),"Unmapped") | M12: =IF(B12<>"",B12&"|"&C12&"|"&D12,"") | N12: =IFERROR(I12/H12,"") | O12: =IFERROR(G12/I12,"") | P12: =IFERROR(G12/H12*1000,"") | Q12: =IFERROR(G12/J12,"") | R12: =IFERROR(K12/G12,"")
L13: =IFERROR(VLOOKUP(M13,Ads_Mapping!$H$2:$I$499,2,FALSE),"Unmapped") | M13: =IF(B13<>"",B13&"|"&C13&"|"&D13,"") | N13: =IFERROR(I13/H13,"") | O13: =IFERROR(G13/I13,"") | P13: =IFERROR(G13/H13*1000,"") | Q13: =IFERROR(G13/J13,"") | R13: =IFERROR(K13/G13,"")
L14: =IFERROR(VLOOKUP(M14,Ads_Mapping!$H$2:$I$499,2,FALSE),"Unmapped") | M14: =IF(B14<>"",B14&"|"&C14&"|"&D14,"") | N14: =IFERROR(I14/H14,"") | O14: =IFERROR(G14/I14,"") | P14: =IFERROR(G14/H14*1000,"") | Q14: =IFERROR(G14/J14,"") | R14: =IFERROR(K14/G14,"")
L15: =IFERROR(VLOOKUP(M15,Ads_Mapping!$H$2:$I$499,2,FALSE),"Unmapped") | M15: =IF(B15<>"",B15&"|"&C15&"|"&D15,"") | N15: =IFERROR(I15/H15,"") | O15: =IFERROR(G15/I15,"") | P15: =IFERROR(G15/H15*1000,"") | Q15: =IFERROR(G15/J15,"") | R15: =IFERROR(K15/G15,"")
... L301: =IFERROR(VLOOKUP(M301,Ads_Mapping!$H$2:$I$499,2,FALSE),"Unmapped") | M301: =IF(B301<>"",B301&"|"&C301&"|"&D301,"") | N301: =IFERROR(I301/H301,"") | O301: =IFERROR(G301/I301,"") | P301: =IFERROR(G301/H301*1000,"") | Q301: =IFERROR(G301/J301,"") | R301: =IFERROR(K301/G301,"")

Sheet Staff_Client_Targets
A1: Staff_ID | B1: Client | C1: Goal_Type (ROAS/CPA) | D1: Target_ROAS | E1: Target_CPA | F1: Notes
A2: S001 | B2: Acme Fitness | C2: ROAS | D2: 3 | F2: Prospecting + retarget blended

Sheet Skill_Summary
A1: Staff_ID | B1: Name | C1: SK01 | D1: SK02 | E1: SK03 | F1: SK04 | G1: SK05 | H1: SK06 | I1: SK07 | J1: SK08 | K1: Skill_Index (0–100)
A2: =IF(Staff!A2<>"",Staff!A2,"") | B2: =IF(A2<>"",VLOOKUP(A2,Staff!$A$2:$B$200,2,FALSE),"") | C2: =IFERROR(SUMIFS(Skill_Assessments!$D$2:$D$500,Skill_Assessments!$B$2:$B$500,$A2,Skill_Assessments!$C$2:$C$500,C1,Skill_Assessments!$A$2:$A$500,">="&Setup!$B$4,Skill_Assessments!$A$2:$A$500,"<="&Setup!$B$5)/COUNTIFS(Skill_Assessments!$B$2:$B$500,$A2,Skill_Assessments!$C$2:$C$500,C1,Skill_Assessments!$A$2:$A$500,">="&Setup!$B$4,Skill_Assessments!$A$2:$A$500,"<="&Setup!$B$5),"") | D2: =IFERROR(SUMIFS(Skill_Assessments!$D$2:$D$500,Skill_Assessments!$B$2:$B$500,$A2,Skill_Assessments!$C$2:$C$500,D1,Skill_Assessments!$A$2:$A$500,">="&Setup!$B$4,Skill_Assessments!$A$2:$A$500,"<="&Setup!$B$5)/COUNTIFS(Skill_Assessments!$B$2:$B$500,$A2,Skill_Assessments!$C$2:$C$500,D1,Skill_Assessments!$A$2:$A$500,">="&Setup!$B$4,Skill_Assessments!$A$2:$A$500,"<="&Setup!$B$5),"") | E2: =IFERROR(SUMIFS(Skill_Assessments!$D$2:$D$500,Skill_Assessments!$B$2:$B$500,$A2,Skill_Assessments!$C$2:$C$500,E1,Skill_Assessments!$A$2:$A$500,">="&Setup!$B$4,Skill_Assessments!$A$2:$A$500,"<="&Setup!$B$5)/COUNTIFS(Skill_Assessments!$B$2:$B$500,$A2,Skill_Assessments!$C$2:$C$500,E1,Skill_Assessments!$A$2:$A$500,">="&Setup!$B$4,Skill_Assessments!$A$2:$A$500,"<="&Setup!$B$5),"") | F2: =IFERROR(SUMIFS(Skill_Assessments!$D$2:$D$500,Skill_Assessments!$B$2:$B$500,$A2,Skill_Assessments!$C$2:$C$500,F1,Skill_Assessments!$A$2:$A$500,">="&Setup!$B$4,Skill_Assessments!$A$2:$A$500,"<="&Setup!$B$5)/COUNTIFS(Skill_Assessments!$B$2:$B$500,$A2,Skill_Assessments!$C$2:$C$500,F1,Skill_Assessments!$A$2:$A$500,">="&Setup!$B$4,Skill_Assessments!$A$2:$A$500,"<="&Setup!$B$5),"") | G2: =IFERROR(SUMIFS(Skill_Assessments!$D$2:$D$500,Skill_Assessments!$B$2:$B$500,$A2,Skill_Assessments!$C$2:$C$500,G1,Skill_Assessments!$A$2:$A$500,">="&Setup!$B$4,Skill_Assessments!$A$2:$A$500,"<="&Setup!$B$5)/COUNTIFS(Skill_Assessments!$B$2:$B$500,$A2,Skill_Assessments!$C$2:$C$500,G1,Skill_Assessments!$A$2:$A$500,">="&Setup!$B$4,Skill_Assessments!$A$2:$A$500,"<="&Setup!$B$5),"") | H2: =IFERROR(SUMIFS(Skill_Assessments!$D$2:$D$500,Skill_Assessments!$B$2:$B$500,$A2,Skill_Assessments!$C$2:$C$500,H1,Skill_Assessments!$A$2:$A$500,">="&Setup!$B$4,Skill_Assessments!$A$2:$A$500,"<="&Setup!$B$5)/COUNTIFS(Skill_Assessments!$B$2:$B$500,$A2,Skill_Assessments!$C$2:$C$500,H1,Skill_Assessments!$A$2:$A$500,">="&Setup!$B$4,Skill_Assessments!$A$2:$A$500,"<="&Setup!$B$5),"") | I2: =IFERROR(SUMIFS(Skill_Assessments!$D$2:$D$500,Skill_Assessments!$B$2:$B$500,$A2,Skill_Assessments!$C$2:$C$500,I1,Skill_Assessments!$A$2:$A$500,">="&Setup!$B$4,Skill_Assessments!$A$2:$A$500,"<="&Setup!$B$5)/COUNTIFS(Skill_Assessments!$B$2:$B$500,$A2,Skill_Assessments!$C$2:$C$500,I1,Skill_Assessments!$A$2:$A$500,">="&Setup!$B$4,Skill_Assessments!$A$2:$A$500,"<="&Setup!$B$5),"") | J2: =IFERROR(SUMIFS(Skill_Assessments!$D$2:$D$500,Skill_Assessments!$B$2:$B$500,$A2,Skill_Assessments!$C$2:$C$500,J1,Skill_Assessments!$A$2:$A$500,">="&Setup!$B$4,Skill_Assessments!$A$2:$A$500,"<="&Setup!$B$5)/COUNTIFS(Skill_Assessments!$B$2:$B$500,$A2,Skill_Assessments!$C$2:$C$500,J1,Skill_Assessments!$A$2:$A$500,">="&Setup!$B$4,Skill_Assessments!$A$2:$A$500,"<="&Setup!$B$5),"") | K2: =IFERROR(SUMPRODUCT(C2:J2,Skills_List!$D$2:$D$9)/(5*SUM(Skills_List!$D$2:$D$9))*100,"")
A3: =IF(Staff!A3<>"",Staff!A3,"") | B3: =IF(A3<>"",VLOOKUP(A3,Staff!$A$2:$B$200,2,FALSE),"") | C3: =IFERROR(SUMIFS(Skill_Assessments!$D$2:$D$500,Skill_Assessments!$B$2:$B$500,$A3,Skill_Assessments!$C$2:$C$500,C1,Skill_Assessments!$A$2:$A$500,">="&Setup!$B$4,Skill_Assessments!$A$2:$A$500,"<="&Setup!$B$5)/COUNTIFS(Skill_Assessments!$B$2:$B$500,$A3,Skill_Assessments!$C$2:$C$500,C1,Skill_Assessments!$A$2:$A$500,">="&Setup!$B$4,Skill_Assessments!$A$2:$A$500,"<="&Setup!$B$5),"") | D3: =IFERROR(SUMIFS(Skill_Assessments!$D$2:$D$500,Skill_Assessments!$B$2:$B$500,$A3,Skill_Assessments!$C$2:$C$500,D1,Skill_Assessments!$A$2:$A$500,">="&Setup!$B$4,Skill_Assessments!$A$2:$A$500,"<="&Setup!$B$5)/COUNTIFS(Skill_Assessments!$B$2:$B$500,$A3,Skill_Assessments!$C$2:$C$500,D1,Skill_Assessments!$A$2:$A$500,">="&Setup!$B$4,Skill_Assessments!$A$2:$A$500,"<="&Setup!$B$5),"") | E3: =IFERROR(SUMIFS(Skill_Assessments!$D$2:$D$500,Skill_Assessments!$B$2:$B$500,$A3,Skill_Assessments!$C$2:$C$500,E1,Skill_Assessments!$A$2:$A$500,">="&Setup!$B$4,Skill_Assessments!$A$2:$A$500,"<="&Setup!$B$5)/COUNTIFS(Skill_Assessments!$B$2:$B$500,$A3,Skill_Assessments!$C$2:$C$500,E1,Skill_Assessments!$A$2:$A$500,">="&Setup!$B$4,Skill_Assessments!$A$2:$A$500,"<="&Setup!$B$5),"") | F3: =IFERROR(SUMIFS(Skill_Assessments!$D$2:$D$500,Skill_Assessments!$B$2:$B$500,$A3,Skill_Assessments!$C$2:$C$500,F1,Skill_Assessments!$A$2:$A$500,">="&Setup!$B$4,Skill_Assessments!$A$2:$A$500,"<="&Setup!$B$5)/COUNTIFS(Skill_Assessments!$B$2:$B$500,$A3,Skill_Assessments!$C$2:$C$500,F1,Skill_Assessments!$A$2:$A$500,">="&Setup!$B$4,Skill_Assessments!$A$2:$A$500,"<="&Setup!$B$5),"") | G3: =IFERROR(SUMIFS(Skill_Assessments!$D$2:$D$500,Skill_Assessments!$B$2:$B$500,$A3,Skill_Assessments!$C$2:$C$500,G1,Skill_Assessments!$A$2:$A$500,">="&Setup!$B$4,Skill_Assessments!$A$2:$A$500,"<="&Setup!$B$5)/COUNTIFS(Skill_Assessments!$B$2:$B$500,$A3,Skill_Assessments!$C$2:$C$500,G1,Skill_Assessments!$A$2:$A$500,">="&Setup!$B$4,Skill_Assessments!$A$2:$A$500,"<="&Setup!$B$5),"") | H3: =IFERROR(SUMIFS(Skill_Assessments!$D$2:$D$500,Skill_Assessments!$B$2:$B$500,$A3,Skill_Assessments!$C$2:$C$500,H1,Skill_Assessments!$A$2:$A$500,">="&Setup!$B$4,Skill_Assessments!$A$2:$A$500,"<="&Setup!$B$5)/COUNTIFS(Skill_Assessments!$B$2:$B$500,$A3,Skill_Assessments!$C$2:$C$500,H1,Skill_Assessments!$A$2:$A$500,">="&Setup!$B$4,Skill_Assessments!$A$2:$A$500,"<="&Setup!$B$5),"") | I3: =IFERROR(SUMIFS(Skill_Assessments!$D$2:$D$500,Skill_Assessments!$B$2:$B$500,$A3,Skill_Assessments!$C$2:$C$500,I1,Skill_Assessments!$A$2:$A$500,">="&Setup!$B$4,Skill_Assessments!$A$2:$A$500,"<="&Setup!$B$5)/COUNTIFS(Skill_Assessments!$B$2:$B$500,$A3,Skill_Assessments!$C$2:$C$500,I1,Skill_Assessments!$A$2:$A$500,">="&Setup!$B$4,Skill_Assessments!$A$2:$A$500,"<="&Setup!$B$5),"") | J3: =IFERROR(SUMIFS(Skill_Assessments!$D$2:$D$500,Skill_Assessments!$B$2:$B$500,$A3,Skill_Assessments!$C$2:$C$500,J1,Skill_Assessments!$A$2:$A$500,">="&Setup!$B$4,Skill_Assessments!$A$2:$A$500,"<="&Setup!$B$5)/COUNTIFS(Skill_Assessments!$B$2:$B$500,$A3,Skill_Assessments!$C$2:$C$500,J1,Skill_Assessments!$A$2:$A$500,">="&Setup!$B$4,Skill_Assessments!$A$2:$A$500,"<="&Setup!$B$5),"") | K3: =IFERROR(SUMPRODUCT(C3:J3,Skills_List!$D$2:$D$9)/(5*SUM(Skills_List!$D$2:$D$9))*100,"")
A4: =IF(Staff!A4<>"",Staff!A4,"") | B4: =IF(A4<>"",VLOOKUP(A4,Staff!$A$2:$B$200,2,FALSE),"") | C4: =IFERROR(SUMIFS(Skill_Assessments!$D$2:$D$500,Skill_Assessments!$B$2:$B$500,$A4,Skill_Assessments!$C$2:$C$500,C1,Skill_Assessments!$A$2:$A$500,">="&Setup!$B$4,Skill_Assessments!$A$2:$A$500,"<="&Setup!$B$5)/COUNTIFS(Skill_Assessments!$B$2:$B$500,$A4,Skill_Assessments!$C$2:$C$500,C1,Skill_Assessments!$A$2:$A$500,">="&Setup!$B$4,Skill_Assessments!$A$2:$A$500,"<="&Setup!$B$5),"") | D4: =IFERROR(SUMIFS(Skill_Assessments!$D$2:$D$500,Skill_Assessments!$B$2:$B$500,$A4,Skill_Assessments!$C$2:$C$500,D1,Skill_Assessments!$A$2:$A$500,">="&Setup!$B$4,Skill_Assessments!$A$2:$A$500,"<="&Setup!$B$5)/COUNTIFS(Skill_Assessments!$B$2:$B$500,$A4,Skill_Assessments!$C$2:$C$500,D1,Skill_Assessments!$A$2:$A$500,">="&Setup!$B$4,Skill_Assessments!$A$2:$A$500,"<="&Setup!$B$5),"") | E4: =IFERROR(SUMIFS(Skill_Assessments!$D$2:$D$500,Skill_Assessments!$B$2:$B$500,$A4,Skill_Assessments!$C$2:$C$500,E1,Skill_Assessments!$A$2:$A$500,">="&Setup!$B$4,Skill_Assessments!$A$2:$A$500,"<="&Setup!$B$5)/COUNTIFS(Skill_Assessments!$B$2:$B$500,$A4,Skill_Assessments!$C$2:$C$500,E1,Skill_Assessments!$A$2:$A$500,">="&Setup!$B$4,Skill_Assessments!$A$2:$A$500,"<="&Setup!$B$5),"") | F4: =IFERROR(SUMIFS(Skill_Assessments!$D$2:$D$500,Skill_Assessments!$B$2:$B$500,$A4,Skill_Assessments!$C$2:$C$500,F1,Skill_Assessments!$A$2:$A$500,">="&Setup!$B$4,Skill_Assessments!$A$2:$A$500,"<="&Setup!$B$5)/COUNTIFS(Skill_Assessments!$B$2:$B$500,$A4,Skill_Assessments!$C$2:$C$500,F1,Skill_Assessments!$A$2:$A$500,">="&Setup!$B$4,Skill_Assessments!$A$2:$A$500,"<="&Setup!$B$5),"") | G4: =IFERROR(SUMIFS(Skill_Assessments!$D$2:$D$500,Skill_Assessments!$B$2:$B$500,$A4,Skill_Assessments!$C$2:$C$500,G1,Skill_Assessments!$A$2:$A$500,">="&Setup!$B$4,Skill_Assessments!$A$2:$A$500,"<="&Setup!$B$5)/COUNTIFS(Skill_Assessments!$B$2:$B$500,$A4,Skill_Assessments!$C$2:$C$500,G1,Skill_Assessments!$A$2:$A$500,">="&Setup!$B$4,Skill_Assessments!$A$2:$A$500,"<="&Setup!$B$5),"") | H4: =IFERROR(SUMIFS(Skill_Assessments!$D$2:$D$500,Skill_Assessments!$B$2:$B$500,$A4,Skill_Assessments!$C$2:$C$500,H1,Skill_Assessments!$A$2:$A$500,">="&Setup!$B$4,Skill_Assessments!$A$2:$A$500,"<="&Setup!$B$5)/COUNTIFS(Skill_Assessments!$B$2:$B$500,$A4,Skill_Assessments!$C$2:$C$500,H1,Skill_Assessments!$A$2:$A$500,">="&Setup!$B$4,Skill_Assessments!$A$2:$A$500,"<="&Setup!$B$5),"") | I4: =IFERROR(SUMIFS(Skill_Assessments!$D$2:$D$500,Skill_Assessments!$B$2:$B$500,$A4,Skill_Assessments!$C$2:$C$500,I1,Skill_Assessments!$A$2:$A$500,">="&Setup!$B$4,Skill_Assessments!$A$2:$A$500,"<="&Setup!$B$5)/COUNTIFS(Skill_Assessments!$B$2:$B$500,$A4,Skill_Assessments!$C$2:$C$500,I1,Skill_Assessments!$A$2:$A$500,">="&Setup!$B$4,Skill_Assessments!$A$2:$A$500,"<="&Setup!$B$5),"") | J4: =IFERROR(SUMIFS(Skill_Assessments!$D$2:$D$500,Skill_Assessments!$B$2:$B$500,$A4,Skill_Assessments!$C$2:$C$500,J1,Skill_Assessments!$A$2:$A$500,">="&Setup!$B$4,Skill_Assessments!$A$2:$A$500,"<="&Setup!$B$5)/COUNTIFS(Skill_Assessments!$B$2:$B$500,$A4,Skill_Assessments!$C$2:$C$500,J1,Skill_Assessments!$A$2:$A$500,">="&Setup!$B$4,Skill_Assessments!$A$2:$A$500,"<="&Setup!$B$5),"") | K4: =IFERROR(SUMPRODUCT(C4:J4,Skills_List!$D$2:$D$9)/(5*SUM(Skills_List!$D$2:$D$9))*100,"")
A5: =IF(Staff!A5<>"",Staff!A5,"") | B5: =IF(A5<>"",VLOOKUP(A5,Staff!$A$2:$B$200,2,FALSE),"") | C5: =IFERROR(SUMIFS(Skill_Assessments!$D$2:$D$500,Skill_Assessments!$B$2:$B$500,$A5,Skill_Assessments!$C$2:$C$500,C1,Skill_Assessments!$A$2:$A$500,">="&Setup!$B$4,Skill_Assessments!$A$2:$A$500,"<="&Setup!$B$5)/COUNTIFS(Skill_Assessments!$B$2:$B$500,$A5,Skill_Assessments!$C$2:$C$500,C1,Skill_Assessments!$A$2:$A$500,">="&Setup!$B$4,Skill_Assessments!$A$2:$A$500,"<="&Setup!$B$5),"") | D5: =IFERROR(SUMIFS(Skill_Assessments!$D$2:$D$500,Skill_Assessments!$B$2:$B$500,$A5,Skill_Assessments!$C$2:$C$500,D1,Skill_Assessments!$A$2:$A$500,">="&Setup!$B$4,Skill_Assessments!$A$2:$A$500,"<="&Setup!$B$5)/COUNTIFS(Skill_Assessments!$B$2:$B$500,$A5,Skill_Assessments!$C$2:$C$500,D1,Skill_Assessments!$A$2:$A$500,">="&Setup!$B$4,Skill_Assessments!$A$2:$A$500,"<="&Setup!$B$5),"") | E5: =IFERROR(SUMIFS(Skill_Assessments!$D$2:$D$500,Skill_Assessments!$B$2:$B$500,$A5,Skill_Assessments!$C$2:$C$500,E1,Skill_Assessments!$A$2:$A$500,">="&Setup!$B$4,Skill_Assessments!$A$2:$A$500,"<="&Setup!$B$5)/COUNTIFS(Skill_Assessments!$B$2:$B$500,$A5,Skill_Assessments!$C$2:$C$500,E1,Skill_Assessments!$A$2:$A$500,">="&Setup!$B$4,Skill_Assessments!$A$2:$A$500,"<="&Setup!$B$5),"") | F5: =IFERROR(SUMIFS(Skill_Assessments!$D$2:$D$500,Skill_Assessments!$B$2:$B$500,$A5,Skill_Assessments!$C$2:$C$500,F1,Skill_Assessments!$A$2:$A$500,">="&Setup!$B$4,Skill_Assessments!$A$2:$A$500,"<="&Setup!$B$5)/COUNTIFS(Skill_Assessments!$B$2:$B$500,$A5,Skill_Assessments!$C$2:$C$500,F1,Skill_Assessments!$A$2:$A$500,">="&Setup!$B$4,Skill_Assessments!$A$2:$A$500,"<="&Setup!$B$5),"") | G5: =IFERROR(SUMIFS(Skill_Assessments!$D$2:$D$500,Skill_Assessments!$B$2:$B$500,$A5,Skill_Assessments!$C$2:$C$500,G1,Skill_Assessments!$A$2:$A$500,">="&Setup!$B$4,Skill_Assessments!$A$2:$A$500,"<="&Setup!$B$5)/COUNTIFS(Skill_Assessments!$B$2:$B$500,$A5,Skill_Assessments!$C$2:$C$500,G1,Skill_Assessments!$A$2:$A$500,">="&Setup!$B$4,Skill_Assessments!$A$2:$A$500,"<="&Setup!$B$5),"") | H5: =IFERROR(SUMIFS(Skill_Assessments!$D$2:$D$500,Skill_Assessments!$B$2:$B$500,$A5,Skill_Assessments!$C$2:$C$500,H1,Skill_Assessments!$A$2:$A$500,">="&Setup!$B$4,Skill_Assessments!$A$2:$A$500,"<="&Setup!$B$5)/COUNTIFS(Skill_Assessments!$B$2:$B$500,$A5,Skill_Assessments!$C$2:$C$500,H1,Skill_Assessments!$A$2:$A$500,">="&Setup!$B$4,Skill_Assessments!$A$2:$A$500,"<="&Setup!$B$5),"") | I5: =IFERROR(SUMIFS(Skill_Assessments!$D$2:$D$500,Skill_Assessments!$B$2:$B$500,$A5,Skill_Assessments!$C$2:$C$500,I1,Skill_Assessments!$A$2:$A$500,">="&Setup!$B$4,Skill_Assessments!$A$2:$A$500,"<="&Setup!$B$5)/COUNTIFS(Skill_Assessments!$B$2:$B$500,$A5,Skill_Assessments!$C$2:$C$500,I1,Skill_Assessments!$A$2:$A$500,">="&Setup!$B$4,Skill_Assessments!$A$2:$A$500,"<="&Setup!$B$5),"") | J5: =IFERROR(SUMIFS(Skill_Assessments!$D$2:$D$500,Skill_Assessments!$B$2:$B$500,$A5,Skill_Assessments!$C$2:$C$500,J1,Skill_Assessments!$A$2:$A$500,">="&Setup!$B$4,Skill_Assessments!$A$2:$A$500,"<="&Setup!$B$5)/COUNTIFS(Skill_Assessments!$B$2:$B$500,$A5,Skill_Assessments!$C$2:$C$500,J1,Skill_Assessments!$A$2:$A$500,">="&Setup!$B$4,Skill_Assessments!$A$2:$A$500,"<="&Setup!$B$5),"") | K5: =IFERROR(SUMPRODUCT(C5:J5,Skills_List!$D$2:$D$9)/(5*SUM(Skills_List!$D$2:$D$9))*100,"")
A6: =IF(Staff!A6<>"",Staff!A6,"") | B6: =IF(A6<>"",VLOOKUP(A6,Staff!$A$2:$B$200,2,FALSE),"") | C6: =IFERROR(SUMIFS(Skill_Assessments!$D$2:$D$500,Skill_Assessments!$B$2:$B$500,$A6,Skill_Assessments!$C$2:$C$500,C1,Skill_Assessments!$A$2:$A$500,">="&Setup!$B$4,Skill_Assessments!$A$2:$A$500,"<="&Setup!$B$5)/COUNTIFS(Skill_Assessments!$B$2:$B$500,$A6,Skill_Assessments!$C$2:$C$500,C1,Skill_Assessments!$A$2:$A$500,">="&Setup!$B$4,Skill_Assessments!$A$2:$A$500,"<="&Setup!$B$5),"") | D6: =IFERROR(SUMIFS(Skill_Assessments!$D$2:$D$500,Skill_Assessments!$B$2:$B$500,$A6,Skill_Assessments!$C$2:$C$500,D1,Skill_Assessments!$A$2:$A$500,">="&Setup!$B$4,Skill_Assessments!$A$2:$A$500,"<="&Setup!$B$5)/COUNTIFS(Skill_Assessments!$B$2:$B$500,$A6,Skill_Assessments!$C$2:$C$500,D1,Skill_Assessments!$A$2:$A$500,">="&Setup!$B$4,Skill_Assessments!$A$2:$A$500,"<="&Setup!$B$5),"") | E6: =IFERROR(SUMIFS(Skill_Assessments!$D$2:$D$500,Skill_Assessments!$B$2:$B$500,$A6,Skill_Assessments!$C$2:$C$500,E1,Skill_Assessments!$A$2:$A$500,">="&Setup!$B$4,Skill_Assessments!$A$2:$A$500,"<="&Setup!$B$5)/COUNTIFS(Skill_Assessments!$B$2:$B$500,$A6,Skill_Assessments!$C$2:$C$500,E1,Skill_Assessments!$A$2:$A$500,">="&Setup!$B$4,Skill_Assessments!$A$2:$A$500,"<="&Setup!$B$5),"") | F6: =IFERROR(SUMIFS(Skill_Assessments!$D$2:$D$500,Skill_Assessments!$B$2:$B$500,$A6,Skill_Assessments!$C$2:$C$500,F1,Skill_Assessments!$A$2:$A$500,">="&Setup!$B$4,Skill_Assessments!$A$2:$A$500,"<="&Setup!$B$5)/COUNTIFS(Skill_Assessments!$B$2:$B$500,$A6,Skill_Assessments!$C$2:$C$500,F1,Skill_Assessments!$A$2:$A$500,">="&Setup!$B$4,Skill_Assessments!$A$2:$A$500,"<="&Setup!$B$5),"") | G6: =IFERROR(SUMIFS(Skill_Assessments!$D$2:$D$500,Skill_Assessments!$B$2:$B$500,$A6,Skill_Assessments!$C$2:$C$500,G1,Skill_Assessments!$A$2:$A$500,">="&Setup!$B$4,Skill_Assessments!$A$2:$A$500,"<="&Setup!$B$5)/COUNTIFS(Skill_Assessments!$B$2:$B$500,$A6,Skill_Assessments!$C$2:$C$500,G1,Skill_Assessments!$A$2:$A$500,">="&Setup!$B$4,Skill_Assessments!$A$2:$A$500,"<="&Setup!$B$5),"") | H6: =IFERROR(SUMIFS(Skill_Assessments!$D$2:$D$500,Skill_Assessments!$B$2:$B$500,$A6,Skill_Assessments!$C$2:$C$500,H1,Skill_Assessments!$A$2:$A$500,">="&Setup!$B$4,Skill_Assessments!$A$2:$A$500,"<="&Setup!$B$5)/COUNTIFS(Skill_Assessments!$B$2:$B$500,$A6,Skill_Assessments!$C$2:$C$500,H1,Skill_Assessments!$A$2:$A$500,">="&Setup!$B$4,Skill_Assessments!$A$2:$A$500,"<="&Setup!$B$5),"") | I6: =IFERROR(SUMIFS(Skill_Assessments!$D$2:$D$500,Skill_Assessments!$B$2:$B$500,$A6,Skill_Assessments!$C$2:$C$500,I1,Skill_Assessments!$A$2:$A$500,">="&Setup!$B$4,Skill_Assessments!$A$2:$A$500,"<="&Setup!$B$5)/COUNTIFS(Skill_Assessments!$B$2:$B$500,$A6,Skill_Assessments!$C$2:$C$500,I1,Skill_Assessments!$A$2:$A$500,">="&Setup!$B$4,Skill_Assessments!$A$2:$A$500,"<="&Setup!$B$5),"") | J6: =IFERROR(SUMIFS(Skill_Assessments!$D$2:$D$500,Skill_Assessments!$B$2:$B$500,$A6,Skill_Assessments!$C$2:$C$500,J1,Skill_Assessments!$A$2:$A$500,">="&Setup!$B$4,Skill_Assessments!$A$2:$A$500,"<="&Setup!$B$5)/COUNTIFS(Skill_Assessments!$B$2:$B$500,$A6,Skill_Assessments!$C$2:$C$500,J1,Skill_Assessments!$A$2:$A$500,">="&Setup!$B$4,Skill_Assessments!$A$2:$A$500,"<="&Setup!$B$5),"") | K6: =IFERROR(SUMPRODUCT(C6:J6,Skills_List!$D$2:$D$9)/(5*SUM(Skills_List!$D$2:$D$9))*100,"")
A7: =IF(Staff!A7<>"",Staff!A7,"") | B7: =IF(A7<>"",VLOOKUP(A7,Staff!$A$2:$B$200,2,FALSE),"") | C7: =IFERROR(SUMIFS(Skill_Assessments!$D$2:$D$500,Skill_Assessments!$B$2:$B$500,$A7,Skill_Assessments!$C$2:$C$500,C1,Skill_Assessments!$A$2:$A$500,">="&Setup!$B$4,Skill_Assessments!$A$2:$A$500,"<="&Setup!$B$5)/COUNTIFS(Skill_Assessments!$B$2:$B$500,$A7,Skill_Assessments!$C$2:$C$500,C1,Skill_Assessments!$A$2:$A$500,">="&Setup!$B$4,Skill_Assessments!$A$2:$A$500,"<="&Setup!$B$5),"") | D7: =IFERROR(SUMIFS(Skill_Assessments!$D$2:$D$500,Skill_Assessments!$B$2:$B$500,$A7,Skill_Assessments!$C$2:$C$500,D1,Skill_Assessments!$A$2:$A$500,">="&Setup!$B$4,Skill_Assessments!$A$2:$A$500,"<="&Setup!$B$5)/COUNTIFS(Skill_Assessments!$B$2:$B$500,$A7,Skill_Assessments!$C$2:$C$500,D1,Skill_Assessments!$A$2:$A$500,">="&Setup!$B$4,Skill_Assessments!$A$2:$A$500,"<="&Setup!$B$5),"") | E7: =IFERROR(SUMIFS(Skill_Assessments!$D$2:$D$500,Skill_Assessments!$B$2:$B$500,$A7,Skill_Assessments!$C$2:$C$500,E1,Skill_Assessments!$A$2:$A$500,">="&Setup!$B$4,Skill_Assessments!$A$2:$A$500,"<="&Setup!$B$5)/COUNTIFS(Skill_Assessments!$B$2:$B$500,$A7,Skill_Assessments!$C$2:$C$500,E1,Skill_Assessments!$A$2:$A$500,">="&Setup!$B$4,Skill_Assessments!$A$2:$A$500,"<="&Setup!$B$5),"") | F7: =IFERROR(SUMIFS(Skill_Assessments!$D$2:$D$500,Skill_Assessments!$B$2:$B$500,$A7,Skill_Assessments!$C$2:$C$500,F1,Skill_Assessments!$A$2:$A$500,">="&Setup!$B$4,Skill_Assessments!$A$2:$A$500,"<="&Setup!$B$5)/COUNTIFS(Skill_Assessments!$B$2:$B$500,$A7,Skill_Assessments!$C$2:$C$500,F1,Skill_Assessments!$A$2:$A$500,">="&Setup!$B$4,Skill_Assessments!$A$2:$A$500,"<="&Setup!$B$5),"") | G7: =IFERROR(SUMIFS(Skill_Assessments!$D$2:$D$500,Skill_Assessments!$B$2:$B$500,$A7,Skill_Assessments!$C$2:$C$500,G1,Skill_Assessments!$A$2:$A$500,">="&Setup!$B$4,Skill_Assessments!$A$2:$A$500,"<="&Setup!$B$5)/COUNTIFS(Skill_Assessments!$B$2:$B$500,$A7,Skill_Assessments!$C$2:$C$500,G1,Skill_Assessments!$A$2:$A$500,">="&Setup!$B$4,Skill_Assessments!$A$2:$A$500,"<="&Setup!$B$5),"") | H7: =IFERROR(SUMIFS(Skill_Assessments!$D$2:$D$500,Skill_Assessments!$B$2:$B$500,$A7,Skill_Assessments!$C$2:$C$500,H1,Skill_Assessments!$A$2:$A$500,">="&Setup!$B$4,Skill_Assessments!$A$2:$A$500,"<="&Setup!$B$5)/COUNTIFS(Skill_Assessments!$B$2:$B$500,$A7,Skill_Assessments!$C$2:$C$500,H1,Skill_Assessments!$A$2:$A$500,">="&Setup!$B$4,Skill_Assessments!$A$2:$A$500,"<="&Setup!$B$5),"") | I7: =IFERROR(SUMIFS(Skill_Assessments!$D$2:$D$500,Skill_Assessments!$B$2:$B$500,$A7,Skill_Assessments!$C$2:$C$500,I1,Skill_Assessments!$A$2:$A$500,">="&Setup!$B$4,Skill_Assessments!$A$2:$A$500,"<="&Setup!$B$5)/COUNTIFS(Skill_Assessments!$B$2:$B$500,$A7,Skill_Assessments!$C$2:$C$500,I1,Skill_Assessments!$A$2:$A$500,">="&Setup!$B$4,Skill_Assessments!$A$2:$A$500,"<="&Setup!$B$5),"") | J7: =IFERROR(SUMIFS(Skill_Assessments!$D$2:$D$500,Skill_Assessments!$B$2:$B$500,$A7,Skill_Assessments!$C$2:$C$500,J1,Skill_Assessments!$A$2:$A$500,">="&Setup!$B$4,Skill_Assessments!$A$2:$A$500,"<="&Setup!$B$5)/COUNTIFS(Skill_Assessments!$B$2:$B$500,$A7,Skill_Assessments!$C$2:$C$500,J1,Skill_Assessments!$A$2:$A$500,">="&Setup!$B$4,Skill_Assessments!$A$2:$A$500,"<="&Setup!$B$5),"") | K7: =IFERROR(SUMPRODUCT(C7:J7,Skills_List!$D$2:$D$9)/(5*SUM(Skills_List!$D$2:$D$9))*100,"")
A8: =IF(Staff!A8<>"",Staff!A8,"") | B8: =IF(A8<>"",VLOOKUP(A8,Staff!$A$2:$B$200,2,FALSE),"") | C8: =IFERROR(SUMIFS(Skill_Assessments!$D$2:$D$500,Skill_Assessments!$B$2:$B$500,$A8,Skill_Assessments!$C$2:$C$500,C1,Skill_Assessments!$A$2:$A$500,">="&Setup!$B$4,Skill_Assessments!$A$2:$A$500,"<="&Setup!$B$5)/COUNTIFS(Skill_Assessments!$B$2:$B$500,$A8,Skill_Assessments!$C$2:$C$500,C1,Skill_Assessments!$A$2:$A$500,">="&Setup!$B$4,Skill_Assessments!$A$2:$A$500,"<="&Setup!$B$5),"") | D8: =IFERROR(SUMIFS(Skill_Assessments!$D$2:$D$500,Skill_Assessments!$B$2:$B$500,$A8,Skill_Assessments!$C$2:$C$500,D1,Skill_Assessments!$A$2:$A$500,">="&Setup!$B$4,Skill_Assessments!$A$2:$A$500,"<="&Setup!$B$5)/COUNTIFS(Skill_Assessments!$B$2:$B$500,$A8,Skill_Assessments!$C$2:$C$500,D1,Skill_Assessments!$A$2:$A$500,">="&Setup!$B$4,Skill_Assessments!$A$2:$A$500,"<="&Setup!$B$5),"") | E8: =IFERROR(SUMIFS(Skill_Assessments!$D$2:$D$500,Skill_Assessments!$B$2:$B$500,$A8,Skill_Assessments!$C$2:$C$500,E1,Skill_Assessments!$A$2:$A$500,">="&Setup!$B$4,Skill_Assessments!$A$2:$A$500,"<="&Setup!$B$5)/COUNTIFS(Skill_Assessments!$B$2:$B$500,$A8,Skill_Assessments!$C$2:$C$500,E1,Skill_Assessments!$A$2:$A$500,">="&Setup!$B$4,Skill_Assessments!$A$2:$A$500,"<="&Setup!$B$5),"") | F8: =IFERROR(SUMIFS(Skill_Assessments!$D$2:$D$500,Skill_Assessments!$B$2:$B$500,$A8,Skill_Assessments!$C$2:$C$500,F1,Skill_Assessments!$A$2:$A$500,">="&Setup!$B$4,Skill_Assessments!$A$2:$A$500,"<="&Setup!$B$5)/COUNTIFS(Skill_Assessments!$B$2:$B$500,$A8,Skill_Assessments!$C$2:$C$500,F1,Skill_Assessments!$A$2:$A$500,">="&Setup!$B$4,Skill_Assessments!$A$2:$A$500,"<="&Setup!$B$5),"") | G8: =IFERROR(SUMIFS(Skill_Assessments!$D$2:$D$500,Skill_Assessments!$B$2:$B$500,$A8,Skill_Assessments!$C$2:$C$500,G1,Skill_Assessments!$A$2:$A$500,">="&Setup!$B$4,Skill_Assessments!$A$2:$A$500,"<="&Setup!$B$5)/COUNTIFS(Skill_Assessments!$B$2:$B$500,$A8,Skill_Assessments!$C$2:$C$500,G1,Skill_Assessments!$A$2:$A$500,">="&Setup!$B$4,Skill_Assessments!$A$2:$A$500,"<="&Setup!$B$5),"") | H8: =IFERROR(SUMIFS(Skill_Assessments!$D$2:$D$500,Skill_Assessments!$B$2:$B$500,$A8,Skill_Assessments!$C$2:$C$500,H1,Skill_Assessments!$A$2:$A$500,">="&Setup!$B$4,Skill_Assessments!$A$2:$A$500,"<="&Setup!$B$5)/COUNTIFS(Skill_Assessments!$B$2:$B$500,$A8,Skill_Assessments!$C$2:$C$500,H1,Skill_Assessments!$A$2:$A$500,">="&Setup!$B$4,Skill_Assessments!$A$2:$A$500,"<="&Setup!$B$5),"") | I8: =IFERROR(SUMIFS(Skill_Assessments!$D$2:$D$500,Skill_Assessments!$B$2:$B$500,$A8,Skill_Assessments!$C$2:$C$500,I1,Skill_Assessments!$A$2:$A$500,">="&Setup!$B$4,Skill_Assessments!$A$2:$A$500,"<="&Setup!$B$5)/COUNTIFS(Skill_Assessments!$B$2:$B$500,$A8,Skill_Assessments!$C$2:$C$500,I1,Skill_Assessments!$A$2:$A$500,">="&Setup!$B$4,Skill_Assessments!$A$2:$A$500,"<="&Setup!$B$5),"") | J8: =IFERROR(SUMIFS(Skill_Assessments!$D$2:$D$500,Skill_Assessments!$B$2:$B$500,$A8,Skill_Assessments!$C$2:$C$500,J1,Skill_Assessments!$A$2:$A$500,">="&Setup!$B$4,Skill_Assessments!$A$2:$A$500,"<="&Setup!$B$5)/COUNTIFS(Skill_Assessments!$B$2:$B$500,$A8,Skill_Assessments!$C$2:$C$500,J1,Skill_Assessments!$A$2:$A$500,">="&Setup!$B$4,Skill_Assessments!$A$2:$A$500,"<="&Setup!$B$5),"") | K8: =IFERROR(SUMPRODUCT(C8:J8,Skills_List!$D$2:$D$9)/(5*SUM(Skills_List!$D$2:$D$9))*100,"")
A9: =IF(Staff!A9<>"",Staff!A9,"") | B9: =IF(A9<>"",VLOOKUP(A9,Staff!$A$2:$B$200,2,FALSE),"") | C9: =IFERROR(SUMIFS(Skill_Assessments!$D$2:$D$500,Skill_Assessments!$B$2:$B$500,$A9,Skill_Assessments!$C$2:$C$500,C1,Skill_Assessments!$A$2:$A$500,">="&Setup!$B$4,Skill_Assessments!$A$2:$A$500,"<="&Setup!$B$5)/COUNTIFS(Skill_Assessments!$B$2:$B$500,$A9,Skill_Assessments!$C$2:$C$500,C1,Skill_Assessments!$A$2:$A$500,">="&Setup!$B$4,Skill_Assessments!$A$2:$A$500,"<="&Setup!$B$5),"") | D9: =IFERROR(SUMIFS(Skill_Assessments!$D$2:$D$500,Skill_Assessments!$B$2:$B$500,$A9,Skill_Assessments!$C$2:$C$500,D1,Skill_Assessments!$A$2:$A$500,">="&Setup!$B$4,Skill_Assessments!$A$2:$A$500,"<="&Setup!$B$5)/COUNTIFS(Skill_Assessments!$B$2:$B$500,$A9,Skill_Assessments!$C$2:$C$500,D1,Skill_Assessments!$A$2:$A$500,">="&Setup!$B$4,Skill_Assessments!$A$2:$A$500,"<="&Setup!$B$5),"") | E9: =IFERROR(SUMIFS(Skill_Assessments!$D$2:$D$500,Skill_Assessments!$B$2:$B$500,$A9,Skill_Assessments!$C$2:$C$500,E1,Skill_Assessments!$A$2:$A$500,">="&Setup!$B$4,Skill_Assessments!$A$2:$A$500,"<="&Setup!$B$5)/COUNTIFS(Skill_Assessments!$B$2:$B$500,$A9,Skill_Assessments!$C$2:$C$500,E1,Skill_Assessments!$A$2:$A$500,">="&Setup!$B$4,Skill_Assessments!$A$2:$A$500,"<="&Setup!$B$5),"") | F9: =IFERROR(SUMIFS(Skill_Assessments!$D$2:$D$500,Skill_Assessments!$B$2:$B$500,$A9,Skill_Assessments!$C$2:$C$500,F1,Skill_Assessments!$A$2:$A$500,">="&Setup!$B$4,Skill_Assessments!$A$2:$A$500,"<="&Setup!$B$5)/COUNTIFS(Skill_Assessments!$B$2:$B$500,$A9,Skill_Assessments!$C$2:$C$500,F1,Skill_Assessments!$A$2:$A$500,">="&Setup!$B$4,Skill_Assessments!$A$2:$A$500,"<="&Setup!$B$5),"") | G9: =IFERROR(SUMIFS(Skill_Assessments!$D$2:$D$500,Skill_Assessments!$B$2:$B$500,$A9,Skill_Assessments!$C$2:$C$500,G1,Skill_Assessments!$A$2:$A$500,">="&Setup!$B$4,Skill_Assessments!$A$2:$A$500,"<="&Setup!$B$5)/COUNTIFS(Skill_Assessments!$B$2:$B$500,$A9,Skill_Assessments!$C$2:$C$500,G1,Skill_Assessments!$A$2:$A$500,">="&Setup!$B$4,Skill_Assessments!$A$2:$A$500,"<="&Setup!$B$5),"") | H9: =IFERROR(SUMIFS(Skill_Assessments!$D$2:$D$500,Skill_Assessments!$B$2:$B$500,$A9,Skill_Assessments!$C$2:$C$500,H1,Skill_Assessments!$A$2:$A$500,">="&Setup!$B$4,Skill_Assessments!$A$2:$A$500,"<="&Setup!$B$5)/COUNTIFS(Skill_Assessments!$B$2:$B$500,$A9,Skill_Assessments!$C$2:$C$500,H1,Skill_Assessments!$A$2:$A$500,">="&Setup!$B$4,Skill_Assessments!$A$2:$A$500,"<="&Setup!$B$5),"") | I9: =IFERROR(SUMIFS(Skill_Assessments!$D$2:$D$500,Skill_Assessments!$B$2:$B$500,$A9,Skill_Assessments!$C$2:$C$500,I1,Skill_Assessments!$A$2:$A$500,">="&Setup!$B$4,Skill_Assessments!$A$2:$A$500,"<="&Setup!$B$5)/COUNTIFS(Skill_Assessments!$B$2:$B$500,$A9,Skill_Assessments!$C$2:$C$500,I1,Skill_Assessments!$A$2:$A$500,">="&Setup!$B$4,Skill_Assessments!$A$2:$A$500,"<="&Setup!$B$5),"") | J9: =IFERROR(SUMIFS(Skill_Assessments!$D$2:$D$500,Skill_Assessments!$B$2:$B$500,$A9,Skill_Assessments!$C$2:$C$500,J1,Skill_Assessments!$A$2:$A$500,">="&Setup!$B$4,Skill_Assessments!$A$2:$A$500,"<="&Setup!$B$5)/COUNTIFS(Skill_Assessments!$B$2:$B$500,$A9,Skill_Assessments!$C$2:$C$500,J1,Skill_Assessments!$A$2:$A$500,">="&Setup!$B$4,Skill_Assessments!$A$2:$A$500,"<="&Setup!$B$5),"") | K9: =IFERROR(SUMPRODUCT(C9:J9,Skills_List!$D$2:$D$9)/(5*SUM(Skills_List!$D$2:$D$9))*100,"")
A10: =IF(Staff!A10<>"",Staff!A10,"") | B10: =IF(A10<>"",VLOOKUP(A10,Staff!$A$2:$B$200,2,FALSE),"") | C10: =IFERROR(SUMIFS(Skill_Assessments!$D$2:$D$500,Skill_Assessments!$B$2:$B$500,$A10,Skill_Assessments!$C$2:$C$500,C1,Skill_Assessments!$A$2:$A$500,">="&Setup!$B$4,Skill_Assessments!$A$2:$A$500,"<="&Setup!$B$5)/COUNTIFS(Skill_Assessments!$B$2:$B$500,$A10,Skill_Assessments!$C$2:$C$500,C1,Skill_Assessments!$A$2:$A$500,">="&Setup!$B$4,Skill_Assessments!$A$2:$A$500,"<="&Setup!$B$5),"") | D10: =IFERROR(SUMIFS(Skill_Assessments!$D$2:$D$500,Skill_Assessments!$B$2:$B$500,$A10,Skill_Assessments!$C$2:$C$500,D1,Skill_Assessments!$A$2:$A$500,">="&Setup!$B$4,Skill_Assessments!$A$2:$A$500,"<="&Setup!$B$5)/COUNTIFS(Skill_Assessments!$B$2:$B$500,$A10,Skill_Assessments!$C$2:$C$500,D1,Skill_Assessments!$A$2:$A$500,">="&Setup!$B$4,Skill_Assessments!$A$2:$A$500,"<="&Setup!$B$5),"") | E10: =IFERROR(SUMIFS(Skill_Assessments!$D$2:$D$500,Skill_Assessments!$B$2:$B$500,$A10,Skill_Assessments!$C$2:$C$500,E1,Skill_Assessments!$A$2:$A$500,">="&Setup!$B$4,Skill_Assessments!$A$2:$A$500,"<="&Setup!$B$5)/COUNTIFS(Skill_Assessments!$B$2:$B$500,$A10,Skill_Assessments!$C$2:$C$500,E1,Skill_Assessments!$A$2:$A$500,">="&Setup!$B$4,Skill_Assessments!$A$2:$A$500,"<="&Setup!$B$5),"") | F10: =IFERROR(SUMIFS(Skill_Assessments!$D$2:$D$500,Skill_Assessments!$B$2:$B$500,$A10,Skill_Assessments!$C$2:$C$500,F1,Skill_Assessments!$A$2:$A$500,">="&Setup!$B$4,Skill_Assessments!$A$2:$A$500,"<="&Setup!$B$5)/COUNTIFS(Skill_Assessments!$B$2:$B$500,$A10,Skill_Assessments!$C$2:$C$500,F1,Skill_Assessments!$A$2:$A$500,">="&Setup!$B$4,Skill_Assessments!$A$2:$A$500,"<="&Setup!$B$5),"") | G10: =IFERROR(SUMIFS(Skill_Assessments!$D$2:$D$500,Skill_Assessments!$B$2:$B$500,$A10,Skill_Assessments!$C$2:$C$500,G1,Skill_Assessments!$A$2:$A$500,">="&Setup!$B$4,Skill_Assessments!$A$2:$A$500,"<="&Setup!$B$5)/COUNTIFS(Skill_Assessments!$B$2:$B$500,$A10,Skill_Assessments!$C$2:$C$500,G1,Skill_Assessments!$A$2:$A$500,">="&Setup!$B$4,Skill_Assessments!$A$2:$A$500,"<="&Setup!$B$5),"") | H10: =IFERROR(SUMIFS(Skill_Assessments!$D$2:$D$500,Skill_Assessments!$B$2:$B$500,$A10,Skill_Assessments!$C$2:$C$500,H1,Skill_Assessments!$A$2:$A$500,">="&Setup!$B$4,Skill_Assessments!$A$2:$A$500,"<="&Setup!$B$5)/COUNTIFS(Skill_Assessments!$B$2:$B$500,$A10,Skill_Assessments!$C$2:$C$500,H1,Skill_Assessments!$A$2:$A$500,">="&Setup!$B$4,Skill_Assessments!$A$2:$A$500,"<="&Setup!$B$5),"") | I10: =IFERROR(SUMIFS(Skill_Assessments!$D$2:$D$500,Skill_Assessments!$B$2:$B$500,$A10,Skill_Assessments!$C$2:$C$500,I1,Skill_Assessments!$A$2:$A$500,">="&Setup!$B$4,Skill_Assessments!$A$2:$A$500,"<="&Setup!$B$5)/COUNTIFS(Skill_Assessments!$B$2:$B$500,$A10,Skill_Assessments!$C$2:$C$500,I1,Skill_Assessments!$A$2:$A$500,">="&Setup!$B$4,Skill_Assessments!$A$2:$A$500,"<="&Setup!$B$5),"") | J10: =IFERROR(SUMIFS(Skill_Assessments!$D$2:$D$500,Skill_Assessments!$B$2:$B$500,$A10,Skill_Assessments!$C$2:$C$500,J1,Skill_Assessments!$A$2:$A$500,">="&Setup!$B$4,Skill_Assessments!$A$2:$A$500,"<="&Setup!$B$5)/COUNTIFS(Skill_Assessments!$B$2:$B$500,$A10,Skill_Assessments!$C$2:$C$500,J1,Skill_Assessments!$A$2:$A$500,">="&Setup!$B$4,Skill_Assessments!$A$2:$A$500,"<="&Setup!$B$5),"") | K10: =IFERROR(SUMPRODUCT(C10:J10,Skills_List!$D$2:$D$9)/(5*SUM(Skills_List!$D$2:$D$9))*100,"")
A11: =IF(Staff!A11<>"",Staff!A11,"") | B11: =IF(A11<>"",VLOOKUP(A11,Staff!$A$2:$B$200,2,FALSE),"") | C11: =IFERROR(SUMIFS(Skill_Assessments!$D$2:$D$500,Skill_Assessments!$B$2:$B$500,$A11,Skill_Assessments!$C$2:$C$500,C1,Skill_Assessments!$A$2:$A$500,">="&Setup!$B$4,Skill_Assessments!$A$2:$A$500,"<="&Setup!$B$5)/COUNTIFS(Skill_Assessments!$B$2:$B$500,$A11,Skill_Assessments!$C$2:$C$500,C1,Skill_Assessments!$A$2:$A$500,">="&Setup!$B$4,Skill_Assessments!$A$2:$A$500,"<="&Setup!$B$5),"") | D11: =IFERROR(SUMIFS(Skill_Assessments!$D$2:$D$500,Skill_Assessments!$B$2:$B$500,$A11,Skill_Assessments!$C$2:$C$500,D1,Skill_Assessments!$A$2:$A$500,">="&Setup!$B$4,Skill_Assessments!$A$2:$A$500,"<="&Setup!$B$5)/COUNTIFS(Skill_Assessments!$B$2:$B$500,$A11,Skill_Assessments!$C$2:$C$500,D1,Skill_Assessments!$A$2:$A$500,">="&Setup!$B$4,Skill_Assessments!$A$2:$A$500,"<="&Setup!$B$5),"") | E11: =IFERROR(SUMIFS(Skill_Assessments!$D$2:$D$500,Skill_Assessments!$B$2:$B$500,$A11,Skill_Assessments!$C$2:$C$500,E1,Skill_Assessments!$A$2:$A$500,">="&Setup!$B$4,Skill_Assessments!$A$2:$A$500,"<="&Setup!$B$5)/COUNTIFS(Skill_Assessments!$B$2:$B$500,$A11,Skill_Assessments!$C$2:$C$500,E1,Skill_Assessments!$A$2:$A$500,">="&Setup!$B$4,Skill_Assessments!$A$2:$A$500,"<="&Setup!$B$5),"") | F11: =IFERROR(SUMIFS(Skill_Assessments!$D$2:$D$500,Skill_Assessments!$B$2:$B$500,$A11,Skill_Assessments!$C$2:$C$500,F1,Skill_Assessments!$A$2:$A$500,">="&Setup!$B$4,Skill_Assessments!$A$2:$A$500,"<="&Setup!$B$5)/COUNTIFS(Skill_Assessments!$B$2:$B$500,$A11,Skill_Assessments!$C$2:$C$500,F1,Skill_Assessments!$A$2:$A$500,">="&Setup!$B$4,Skill_Assessments!$A$2:$A$500,"<="&Setup!$B$5),"") | G11: =IFERROR(SUMIFS(Skill_Assessments!$D$2:$D$500,Skill_Assessments!$B$2:$B$500,$A11,Skill_Assessments!$C$2:$C$500,G1,Skill_Assessments!$A$2:$A$500,">="&Setup!$B$4,Skill_Assessments!$A$2:$A$500,"<="&Setup!$B$5)/COUNTIFS(Skill_Assessments!$B$2:$B$500,$A11,Skill_Assessments!$C$2:$C$500,G1,Skill_Assessments!$A$2:$A$500,">="&Setup!$B$4,Skill_Assessments!$A$2:$A$500,"<="&Setup!$B$5),"") | H11: =IFERROR(SUMIFS(Skill_Assessments!$D$2:$D$500,Skill_Assessments!$B$2:$B$500,$A11,Skill_Assessments!$C$2:$C$500,H1,Skill_Assessments!$A$2:$A$500,">="&Setup!$B$4,Skill_Assessments!$A$2:$A$500,"<="&Setup!$B$5)/COUNTIFS(Skill_Assessments!$B$2:$B$500,$A11,Skill_Assessments!$C$2:$C$500,H1,Skill_Assessments!$A$2:$A$500,">="&Setup!$B$4,Skill_Assessments!$A$2:$A$500,"<="&Setup!$B$5),"") | I11: =IFERROR(SUMIFS(Skill_Assessments!$D$2:$D$500,Skill_Assessments!$B$2:$B$500,$A11,Skill_Assessments!$C$2:$C$500,I1,Skill_Assessments!$A$2:$A$500,">="&Setup!$B$4,Skill_Assessments!$A$2:$A$500,"<="&Setup!$B$5)/COUNTIFS(Skill_Assessments!$B$2:$B$500,$A11,Skill_Assessments!$C$2:$C$500,I1,Skill_Assessments!$A$2:$A$500,">="&Setup!$B$4,Skill_Assessments!$A$2:$A$500,"<="&Setup!$B$5),"") | J11: =IFERROR(SUMIFS(Skill_Assessments!$D$2:$D$500,Skill_Assessments!$B$2:$B$500,$A11,Skill_Assessments!$C$2:$C$500,J1,Skill_Assessments!$A$2:$A$500,">="&Setup!$B$4,Skill_Assessments!$A$2:$A$500,"<="&Setup!$B$5)/COUNTIFS(Skill_Assessments!$B$2:$B$500,$A11,Skill_Assessments!$C$2:$C$500,J1,Skill_Assessments!$A$2:$A$500,">="&Setup!$B$4,Skill_Assessments!$A$2:$A$500,"<="&Setup!$B$5),"") | K11: =IFERROR(SUMPRODUCT(C11:J11,Skills_List!$D$2:$D$9)/(5*SUM(Skills_List!$D$2:$D$9))*100,"")
A12: =IF(Staff!A12<>"",Staff!A12,"") | B12: =IF(A12<>"",VLOOKUP(A12,Staff!$A$2:$B$200,2,FALSE),"") | C12: =IFERROR(SUMIFS(Skill_Assessments!$D$2:$D$500,Skill_Assessments!$B$2:$B$500,$A12,Skill_Assessments!$C$2:$C$500,C1,Skill_Assessments!$A$2:$A$500,">="&Setup!$B$4,Skill_Assessments!$A$2:$A$500,"<="&Setup!$B$5)/COUNTIFS(Skill_Assessments!$B$2:$B$500,$A12,Skill_Assessments!$C$2:$C$500,C1,Skill_Assessments!$A$2:$A$500,">="&Setup!$B$4,Skill_Assessments!$A$2:$A$500,"<="&Setup!$B$5),"") | D12: =IFERROR(SUMIFS(Skill_Assessments!$D$2:$D$500,Skill_Assessments!$B$2:$B$500,$A12,Skill_Assessments!$C$2:$C$500,D1,Skill_Assessments!$A$2:$A$500,">="&Setup!$B$4,Skill_Assessments!$A$2:$A$500,"<="&Setup!$B$5)/COUNTIFS(Skill_Assessments!$B$2:$B$500,$A12,Skill_Assessments!$C$2:$C$500,D1,Skill_Assessments!$A$2:$A$500,">="&Setup!$B$4,Skill_Assessments!$A$2:$A$500,"<="&Setup!$B$5),"") | E12: =IFERROR(SUMIFS(Skill_Assessments!$D$2:$D$500,Skill_Assessments!$B$2:$B$500,$A12,Skill_Assessments!$C$2:$C$500,E1,Skill_Assessments!$A$2:$A$500,">="&Setup!$B$4,Skill_Assessments!$A$2:$A$500,"<="&Setup!$B$5)/COUNTIFS(Skill_Assessments!$B$2:$B$500,$A12,Skill_Assessments!$C$2:$C$500,E1,Skill_Assessments!$A$2:$A$500,">="&Setup!$B$4,Skill_Assessments!$A$2:$A$500,"<="&Setup!$B$5),"") | F12: =IFERROR(SUMIFS(Skill_Assessments!$D$2:$D$500,Skill_Assessments!$B$2:$B$500,$A12,Skill_Assessments!$C$2:$C$500,F1,Skill_Assessments!$A$2:$A$500,">="&Setup!$B$4,Skill_Assessments!$A$2:$A$500,"<="&Setup!$B$5)/COUNTIFS(Skill_Assessments!$B$2:$B$500,$A12,Skill_Assessments!$C$2:$C$500,F1,Skill_Assessments!$A$2:$A$500,">="&Setup!$B$4,Skill_Assessments!$A$2:$A$500,"<="&Setup!$B$5),"") | G12: =IFERROR(SUMIFS(Skill_Assessments!$D$2:$D$500,Skill_Assessments!$B$2:$B$500,$A12,Skill_Assessments!$C$2:$C$500,G1,Skill_Assessments!$A$2:$A$500,">="&Setup!$B$4,Skill_Assessments!$A$2:$A$500,"<="&Setup!$B$5)/COUNTIFS(Skill_Assessments!$B$2:$B$500,$A12,Skill_Assessments!$C$2:$C$500,G1,Skill_Assessments!$A$2:$A$500,">="&Setup!$B$4,Skill_Assessments!$A$2:$A$500,"<="&Setup!$B$5),"") | H12: =IFERROR(SUMIFS(Skill_Assessments!$D$2:$D$500,Skill_Assessments!$B$2:$B$500,$A12,Skill_Assessments!$C$2:$C$500,H1,Skill_Assessments!$A$2:$A$500,">="&Setup!$B$4,Skill_Assessments!$A$2:$A$500,"<="&Setup!$B$5)/COUNTIFS(Skill_Assessments!$B$2:$B$500,$A12,Skill_Assessments!$C$2:$C$500,H1,Skill_Assessments!$A$2:$A$500,">="&Setup!$B$4,Skill_Assessments!$A$2:$A$500,"<="&Setup!$B$5),"") | I12: =IFERROR(SUMIFS(Skill_Assessments!$D$2:$D$500,Skill_Assessments!$B$2:$B$500,$A12,Skill_Assessments!$C$2:$C$500,I1,Skill_Assessments!$A$2:$A$500,">="&Setup!$B$4,Skill_Assessments!$A$2:$A$500,"<="&Setup!$B$5)/COUNTIFS(Skill_Assessments!$B$2:$B$500,$A12,Skill_Assessments!$C$2:$C$500,I1,Skill_Assessments!$A$2:$A$500,">="&Setup!$B$4,Skill_Assessments!$A$2:$A$500,"<="&Setup!$B$5),"") | J12: =IFERROR(SUMIFS(Skill_Assessments!$D$2:$D$500,Skill_Assessments!$B$2:$B$500,$A12,Skill_Assessments!$C$2:$C$500,J1,Skill_Assessments!$A$2:$A$500,">="&Setup!$B$4,Skill_Assessments!$A$2:$A$500,"<="&Setup!$B$5)/COUNTIFS(Skill_Assessments!$B$2:$B$500,$A12,Skill_Assessments!$C$2:$C$500,J1,Skill_Assessments!$A$2:$A$500,">="&Setup!$B$4,Skill_Assessments!$A$2:$A$500,"<="&Setup!$B$5),"") | K12: =IFERROR(SUMPRODUCT(C12:J12,Skills_List!$D$2:$D$9)/(5*SUM(Skills_List!$D$2:$D$9))*100,"")
A13: =IF(Staff!A13<>"",Staff!A13,"") | B13: =IF(A13<>"",VLOOKUP(A13,Staff!$A$2:$B$200,2,FALSE),"") | C13: =IFERROR(SUMIFS(Skill_Assessments!$D$2:$D$500,Skill_Assessments!$B$2:$B$500,$A13,Skill_Assessments!$C$2:$C$500,C1,Skill_Assessments!$A$2:$A$500,">="&Setup!$B$4,Skill_Assessments!$A$2:$A$500,"<="&Setup!$B$5)/COUNTIFS(Skill_Assessments!$B$2:$B$500,$A13,Skill_Assessments!$C$2:$C$500,C1,Skill_Assessments!$A$2:$A$500,">="&Setup!$B$4,Skill_Assessments!$A$2:$A$500,"<="&Setup!$B$5),"") | D13: =IFERROR(SUMIFS(Skill_Assessments!$D$2:$D$500,Skill_Assessments!$B$2:$B$500,$A13,Skill_Assessments!$C$2:$C$500,D1,Skill_Assessments!$A$2:$A$500,">="&Setup!$B$4,Skill_Assessments!$A$2:$A$500,"<="&Setup!$B$5)/COUNTIFS(Skill_Assessments!$B$2:$B$500,$A13,Skill_Assessments!$C$2:$C$500,D1,Skill_Assessments!$A$2:$A$500,">="&Setup!$B$4,Skill_Assessments!$A$2:$A$500,"<="&Setup!$B$5),"") | E13: =IFERROR(SUMIFS(Skill_Assessments!$D$2:$D$500,Skill_Assessments!$B$2:$B$500,$A13,Skill_Assessments!$C$2:$C$500,E1,Skill_Assessments!$A$2:$A$500,">="&Setup!$B$4,Skill_Assessments!$A$2:$A$500,"<="&Setup!$B$5)/COUNTIFS(Skill_Assessments!$B$2:$B$500,$A13,Skill_Assessments!$C$2:$C$500,E1,Skill_Assessments!$A$2:$A$500,">="&Setup!$B$4,Skill_Assessments!$A$2:$A$500,"<="&Setup!$B$5),"") | F13: =IFERROR(SUMIFS(Skill_Assessments!$D$2:$D$500,Skill_Assessments!$B$2:$B$500,$A13,Skill_Assessments!$C$2:$C$500,F1,Skill_Assessments!$A$2:$A$500,">="&Setup!$B$4,Skill_Assessments!$A$2:$A$500,"<="&Setup!$B$5)/COUNTIFS(Skill_Assessments!$B$2:$B$500,$A13,Skill_Assessments!$C$2:$C$500,F1,Skill_Assessments!$A$2:$A$500,">="&Setup!$B$4,Skill_Assessments!$A$2:$A$500,"<="&Setup!$B$5),"") | G13: =IFERROR(SUMIFS(Skill_Assessments!$D$2:$D$500,Skill_Assessments!$B$2:$B$500,$A13,Skill_Assessments!$C$2:$C$500,G1,Skill_Assessments!$A$2:$A$500,">="&Setup!$B$4,Skill_Assessments!$A$2:$A$500,"<="&Setup!$B$5)/COUNTIFS(Skill_Assessments!$B$2:$B$500,$A13,Skill_Assessments!$C$2:$C$500,G1,Skill_Assessments!$A$2:$A$500,">="&Setup!$B$4,Skill_Assessments!$A$2:$A$500,"<="&Setup!$B$5),"") | H13: =IFERROR(SUMIFS(Skill_Assessments!$D$2:$D$500,Skill_Assessments!$B$2:$B$500,$A13,Skill_Assessments!$C$2:$C$500,H1,Skill_Assessments!$A$2:$A$500,">="&Setup!$B$4,Skill_Assessments!$A$2:$A$500,"<="&Setup!$B$5)/COUNTIFS(Skill_Assessments!$B$2:$B$500,$A13,Skill_Assessments!$C$2:$C$500,H1,Skill_Assessments!$A$2:$A$500,">="&Setup!$B$4,Skill_Assessments!$A$2:$A$500,"<="&Setup!$B$5),"") | I13: =IFERROR(SUMIFS(Skill_Assessments!$D$2:$D$500,Skill_Assessments!$B$2:$B$500,$A13,Skill_Assessments!$C$2:$C$500,I1,Skill_Assessments!$A$2:$A$500,">="&Setup!$B$4,Skill_Assessments!$A$2:$A$500,"<="&Setup!$B$5)/COUNTIFS(Skill_Assessments!$B$2:$B$500,$A13,Skill_Assessments!$C$2:$C$500,I1,Skill_Assessments!$A$2:$A$500,">="&Setup!$B$4,Skill_Assessments!$A$2:$A$500,"<="&Setup!$B$5),"") | J13: =IFERROR(SUMIFS(Skill_Assessments!$D$2:$D$500,Skill_Assessments!$B$2:$B$500,$A13,Skill_Assessments!$C$2:$C$500,J1,Skill_Assessments!$A$2:$A$500,">="&Setup!$B$4,Skill_Assessments!$A$2:$A$500,"<="&Setup!$B$5)/COUNTIFS(Skill_Assessments!$B$2:$B$500,$A13,Skill_Assessments!$C$2:$C$500,J1,Skill_Assessments!$A$2:$A$500,">="&Setup!$B$4,Skill_Assessments!$A$2:$A$500,"<="&Setup!$B$5),"") | K13: =IFERROR(SUMPRODUCT(C13:J13,Skills_List!$D$2:$D$9)/(5*SUM(Skills_List!$D$2:$D$9))*100,"")
A14: =IF(Staff!A14<>"",Staff!A14,"") | B14: =IF(A14<>"",VLOOKUP(A14,Staff!$A$2:$B$200,2,FALSE),"") | C14: =IFERROR(SUMIFS(Skill_Assessments!$D$2:$D$500,Skill_Assessments!$B$2:$B$500,$A14,Skill_Assessments!$C$2:$C$500,C1,Skill_Assessments!$A$2:$A$500,">="&Setup!$B$4,Skill_Assessments!$A$2:$A$500,"<="&Setup!$B$5)/COUNTIFS(Skill_Assessments!$B$2:$B$500,$A14,Skill_Assessments!$C$2:$C$500,C1,Skill_Assessments!$A$2:$A$500,">="&Setup!$B$4,Skill_Assessments!$A$2:$A$500,"<="&Setup!$B$5),"") | D14: =IFERROR(SUMIFS(Skill_Assessments!$D$2:$D$500,Skill_Assessments!$B$2:$B$500,$A14,Skill_Assessments!$C$2:$C$500,D1,Skill_Assessments!$A$2:$A$500,">="&Setup!$B$4,Skill_Assessments!$A$2:$A$500,"<="&Setup!$B$5)/COUNTIFS(Skill_Assessments!$B$2:$B$500,$A14,Skill_Assessments!$C$2:$C$500,D1,Skill_Assessments!$A$2:$A$500,">="&Setup!$B$4,Skill_Assessments!$A$2:$A$500,"<="&Setup!$B$5),"") | E14: =IFERROR(SUMIFS(Skill_Assessments!$D$2:$D$500,Skill_Assessments!$B$2:$B$500,$A14,Skill_Assessments!$C$2:$C$500,E1,Skill_Assessments!$A$2:$A$500,">="&Setup!$B$4,Skill_Assessments!$A$2:$A$500,"<="&Setup!$B$5)/COUNTIFS(Skill_Assessments!$B$2:$B$500,$A14,Skill_Assessments!$C$2:$C$500,E1,Skill_Assessments!$A$2:$A$500,">="&Setup!$B$4,Skill_Assessments!$A$2:$A$500,"<="&Setup!$B$5),"") | F14: =IFERROR(SUMIFS(Skill_Assessments!$D$2:$D$500,Skill_Assessments!$B$2:$B$500,$A14,Skill_Assessments!$C$2:$C$500,F1,Skill_Assessments!$A$2:$A$500,">="&Setup!$B$4,Skill_Assessments!$A$2:$A$500,"<="&Setup!$B$5)/COUNTIFS(Skill_Assessments!$B$2:$B$500,$A14,Skill_Assessments!$C$2:$C$500,F1,Skill_Assessments!$A$2:$A$500,">="&Setup!$B$4,Skill_Assessments!$A$2:$A$500,"<="&Setup!$B$5),"") | G14: =IFERROR(SUMIFS(Skill_Assessments!$D$2:$D$500,Skill_Assessments!$B$2:$B$500,$A14,Skill_Assessments!$C$2:$C$500,G1,Skill_Assessments!$A$2:$A$500,">="&Setup!$B$4,Skill_Assessments!$A$2:$A$500,"<="&Setup!$B$5)/COUNTIFS(Skill_Assessments!$B$2:$B$500,$A14,Skill_Assessments!$C$2:$C$500,G1,Skill_Assessments!$A$2:$A$500,">="&Setup!$B$4,Skill_Assessments!$A$2:$A$500,"<="&Setup!$B$5),"") | H14: =IFERROR(SUMIFS(Skill_Assessments!$D$2:$D$500,Skill_Assessments!$B$2:$B$500,$A14,Skill_Assessments!$C$2:$C$500,H1,Skill_Assessments!$A$2:$A$500,">="&Setup!$B$4,Skill_Assessments!$A$2:$A$500,"<="&Setup!$B$5)/COUNTIFS(Skill_Assessments!$B$2:$B$500,$A14,Skill_Assessments!$C$2:$C$500,H1,Skill_Assessments!$A$2:$A$500,">="&Setup!$B$4,Skill_Assessments!$A$2:$A$500,"<="&Setup!$B$5),"") | I14: =IFERROR(SUMIFS(Skill_Assessments!$D$2:$D$500,Skill_Assessments!$B$2:$B$500,$A14,Skill_Assessments!$C$2:$C$500,I1,Skill_Assessments!$A$2:$A$500,">="&Setup!$B$4,Skill_Assessments!$A$2:$A$500,"<="&Setup!$B$5)/COUNTIFS(Skill_Assessments!$B$2:$B$500,$A14,Skill_Assessments!$C$2:$C$500,I1,Skill_Assessments!$A$2:$A$500,">="&Setup!$B$4,Skill_Assessments!$A$2:$A$500,"<="&Setup!$B$5),"") | J14: =IFERROR(SUMIFS(Skill_Assessments!$D$2:$D$500,Skill_Assessments!$B$2:$B$500,$A14,Skill_Assessments!$C$2:$C$500,J1,Skill_Assessments!$A$2:$A$500,">="&Setup!$B$4,Skill_Assessments!$A$2:$A$500,"<="&Setup!$B$5)/COUNTIFS(Skill_Assessments!$B$2:$B$500,$A14,Skill_Assessments!$C$2:$C$500,J1,Skill_Assessments!$A$2:$A$500,">="&Setup!$B$4,Skill_Assessments!$A$2:$A$500,"<="&Setup!$B$5),"") | K14: =IFERROR(SUMPRODUCT(C14:J14,Skills_List!$D$2:$D$9)/(5*SUM(Skills_List!$D$2:$D$9))*100,"")
A15: =IF(Staff!A15<>"",Staff!A15,"") | B15: =IF(A15<>"",VLOOKUP(A15,Staff!$A$2:$B$200,2,FALSE),"") | C15: =IFERROR(SUMIFS(Skill_Assessments!$D$2:$D$500,Skill_Assessments!$B$2:$B$500,$A15,Skill_Assessments!$C$2:$C$500,C1,Skill_Assessments!$A$2:$A$500,">="&Setup!$B$4,Skill_Assessments!$A$2:$A$500,"<="&Setup!$B$5)/COUNTIFS(Skill_Assessments!$B$2:$B$500,$A15,Skill_Assessments!$C$2:$C$500,C1,Skill_Assessments!$A$2:$A$500,">="&Setup!$B$4,Skill_Assessments!$A$2:$A$500,"<="&Setup!$B$5),"") | D15: =IFERROR(SUMIFS(Skill_Assessments!$D$2:$D$500,Skill_Assessments!$B$2:$B$500,$A15,Skill_Assessments!$C$2:$C$500,D1,Skill_Assessments!$A$2:$A$500,">="&Setup!$B$4,Skill_Assessments!$A$2:$A$500,"<="&Setup!$B$5)/COUNTIFS(Skill_Assessments!$B$2:$B$500,$A15,Skill_Assessments!$C$2:$C$500,D1,Skill_Assessments!$A$2:$A$500,">="&Setup!$B$4,Skill_Assessments!$A$2:$A$500,"<="&Setup!$B$5),"") | E15: =IFERROR(SUMIFS(Skill_Assessments!$D$2:$D$500,Skill_Assessments!$B$2:$B$500,$A15,Skill_Assessments!$C$2:$C$500,E1,Skill_Assessments!$A$2:$A$500,">="&Setup!$B$4,Skill_Assessments!$A$2:$A$500,"<="&Setup!$B$5)/COUNTIFS(Skill_Assessments!$B$2:$B$500,$A15,Skill_Assessments!$C$2:$C$500,E1,Skill_Assessments!$A$2:$A$500,">="&Setup!$B$4,Skill_Assessments!$A$2:$A$500,"<="&Setup!$B$5),"") | F15: =IFERROR(SUMIFS(Skill_Assessments!$D$2:$D$500,Skill_Assessments!$B$2:$B$500,$A15,Skill_Assessments!$C$2:$C$500,F1,Skill_Assessments!$A$2:$A$500,">="&Setup!$B$4,Skill_Assessments!$A$2:$A$500,"<="&Setup!$B$5)/COUNTIFS(Skill_Assessments!$B$2:$B$500,$A15,Skill_Assessments!$C$2:$C$500,F1,Skill_Assessments!$A$2:$A$500,">="&Setup!$B$4,Skill_Assessments!$A$2:$A$500,"<="&Setup!$B$5),"") | G15: =IFERROR(SUMIFS(Skill_Assessments!$D$2:$D$500,Skill_Assessments!$B$2:$B$500,$A15,Skill_Assessments!$C$2:$C$500,G1,Skill_Assessments!$A$2:$A$500,">="&Setup!$B$4,Skill_Assessments!$A$2:$A$500,"<="&Setup!$B$5)/COUNTIFS(Skill_Assessments!$B$2:$B$500,$A15,Skill_Assessments!$C$2:$C$500,G1,Skill_Assessments!$A$2:$A$500,">="&Setup!$B$4,Skill_Assessments!$A$2:$A$500,"<="&Setup!$B$5),"") | H15: =IFERROR(SUMIFS(Skill_Assessments!$D$2:$D$500,Skill_Assessments!$B$2:$B$500,$A15,Skill_Assessments!$C$2:$C$500,H1,Skill_Assessments!$A$2:$A$500,">="&Setup!$B$4,Skill_Assessments!$A$2:$A$500,"<="&Setup!$B$5)/COUNTIFS(Skill_Assessments!$B$2:$B$500,$A15,Skill_Assessments!$C$2:$C$500,H1,Skill_Assessments!$A$2:$A$500,">="&Setup!$B$4,Skill_Assessments!$A$2:$A$500,"<="&Setup!$B$5),"") | I15: =IFERROR(SUMIFS(Skill_Assessments!$D$2:$D$500,Skill_Assessments!$B$2:$B$500,$A15,Skill_Assessments!$C$2:$C$500,I1,Skill_Assessments!$A$2:$A$500,">="&Setup!$B$4,Skill_Assessments!$A$2:$A$500,"<="&Setup!$B$5)/COUNTIFS(Skill_Assessments!$B$2:$B$500,$A15,Skill_Assessments!$C$2:$C$500,I1,Skill_Assessments!$A$2:$A$500,">="&Setup!$B$4,Skill_Assessments!$A$2:$A$500,"<="&Setup!$B$5),"") | J15: =IFERROR(SUMIFS(Skill_Assessments!$D$2:$D$500,Skill_Assessments!$B$2:$B$500,$A15,Skill_Assessments!$C$2:$C$500,J1,Skill_Assessments!$A$2:$A$500,">="&Setup!$B$4,Skill_Assessments!$A$2:$A$500,"<="&Setup!$B$5)/COUNTIFS(Skill_Assessments!$B$2:$B$500,$A15,Skill_Assessments!$C$2:$C$500,J1,Skill_Assessments!$A$2:$A$500,">="&Setup!$B$4,Skill_Assessments!$A$2:$A$500,"<="&Setup!$B$5),"") | K15: =IFERROR(SUMPRODUCT(C15:J15,Skills_List!$D$2:$D$9)/(5*SUM(Skills_List!$D$2:$D$9))*100,"")
A16: =IF(Staff!A16<>"",Staff!A16,"") | B16: =IF(A16<>"",VLOOKUP(A16,Staff!$A$2:$B$200,2,FALSE),"") | C16: =IFERROR(SUMIFS(Skill_Assessments!$D$2:$D$500,Skill_Assessments!$B$2:$B$500,$A16,Skill_Assessments!$C$2:$C$500,C1,Skill_Assessments!$A$2:$A$500,">="&Setup!$B$4,Skill_Assessments!$A$2:$A$500,"<="&Setup!$B$5)/COUNTIFS(Skill_Assessments!$B$2:$B$500,$A16,Skill_Assessments!$C$2:$C$500,C1,Skill_Assessments!$A$2:$A$500,">="&Setup!$B$4,Skill_Assessments!$A$2:$A$500,"<="&Setup!$B$5),"") | D16: =IFERROR(SUMIFS(Skill_Assessments!$D$2:$D$500,Skill_Assessments!$B$2:$B$500,$A16,Skill_Assessments!$C$2:$C$500,D1,Skill_Assessments!$A$2:$A$500,">="&Setup!$B$4,Skill_Assessments!$A$2:$A$500,"<="&Setup!$B$5)/COUNTIFS(Skill_Assessments!$B$2:$B$500,$A16,Skill_Assessments!$C$2:$C$500,D1,Skill_Assessments!$A$2:$A$500,">="&Setup!$B$4,Skill_Assessments!$A$2:$A$500,"<="&Setup!$B$5),"") | E16: =IFERROR(SUMIFS(Skill_Assessments!$D$2:$D$500,Skill_Assessments!$B$2:$B$500,$A16,Skill_Assessments!$C$2:$C$500,E1,Skill_Assessments!$A$2:$A$500,">="&Setup!$B$4,Skill_Assessments!$A$2:$A$500,"<="&Setup!$B$5)/COUNTIFS(Skill_Assessments!$B$2:$B$500,$A16,Skill_Assessments!$C$2:$C$500,E1,Skill_Assessments!$A$2:$A$500,">="&Setup!$B$4,Skill_Assessments!$A$2:$A$500,"<="&Setup!$B$5),"") | F16: =IFERROR(SUMIFS(Skill_Assessments!$D$2:$D$500,Skill_Assessments!$B$2:$B$500,$A16,Skill_Assessments!$C$2:$C$500,F1,Skill_Assessments!$A$2:$A$500,">="&Setup!$B$4,Skill_Assessments!$A$2:$A$500,"<="&Setup!$B$5)/COUNTIFS(Skill_Assessments!$B$2:$B$500,$A16,Skill_Assessments!$C$2:$C$500,F1,Skill_Assessments!$A$2:$A$500,">="&Setup!$B$4,Skill_Assessments!$A$2:$A$500,"<="&Setup!$B$5),"") | G16: =IFERROR(SUMIFS(Skill_Assessments!$D$2:$D$500,Skill_Assessments!$B$2:$B$500,$A16,Skill_Assessments!$C$2:$C$500,G1,Skill_Assessments!$A$2:$A$500,">="&Setup!$B$4,Skill_Assessments!$A$2:$A$500,"<="&Setup!$B$5)/COUNTIFS(Skill_Assessments!$B$2:$B$500,$A16,Skill_Assessments!$C$2:$C$500,G1,Skill_Assessments!$A$2:$A$500,">="&Setup!$B$4,Skill_Assessments!$A$2:$A$500,"<="&Setup!$B$5),"") | H16: =IFERROR(SUMIFS(Skill_Assessments!$D$2:$D$500,Skill_Assessments!$B$2:$B$500,$A16,Skill_Assessments!$C$2:$C$500,H1,Skill_Assessments!$A$2:$A$500,">="&Setup!$B$4,Skill_Assessments!$A$2:$A$500,"<="&Setup!$B$5)/COUNTIFS(Skill_Assessments!$B$2:$B$500,$A16,Skill_Assessments!$C$2:$C$500,H1,Skill_Assessments!$A$2:$A$500,">="&Setup!$B$4,Skill_Assessments!$A$2:$A$500,"<="&Setup!$B$5),"") | I16: =IFERROR(SUMIFS(Skill_Assessments!$D$2:$D$500,Skill_Assessments!$B$2:$B$500,$A16,Skill_Assessments!$C$2:$C$500,I1,Skill_Assessments!$A$2:$A$500,">="&Setup!$B$4,Skill_Assessments!$A$2:$A$500,"<="&Setup!$B$5)/COUNTIFS(Skill_Assessments!$B$2:$B$500,$A16,Skill_Assessments!$C$2:$C$500,I1,Skill_Assessments!$A$2:$A$500,">="&Setup!$B$4,Skill_Assessments!$A$2:$A$500,"<="&Setup!$B$5),"") | J16: =IFERROR(SUMIFS(Skill_Assessments!$D$2:$D$500,Skill_Assessments!$B$2:$B$500,$A16,Skill_Assessments!$C$2:$C$500,J1,Skill_Assessments!$A$2:$A$500,">="&Setup!$B$4,Skill_Assessments!$A$2:$A$500,"<="&Setup!$B$5)/COUNTIFS(Skill_Assessments!$B$2:$B$500,$A16,Skill_Assessments!$C$2:$C$500,J1,Skill_Assessments!$A$2:$A$500,">="&Setup!$B$4,Skill_Assessments!$A$2:$A$500,"<="&Setup!$B$5),"") | K16: =IFERROR(SUMPRODUCT(C16:J16,Skills_List!$D$2:$D$9)/(5*SUM(Skills_List!$D$2:$D$9))*100,"")
